Workbook

Sheet data
A1: ranking | B1: name | C1: tag | D1: tier | E1: LP | F1: most1 | G1: most2 | H1: most3 | I1: level | J1: win | K1: lose | L1: win_rate | M1: role | N1: type | P1: 개수 : 역할군 | Q1: 열 레이블 | AJ1: `
A2: 1 | B2: moment | C2: #0619 | D2: Challenger | E2: 2041 | F2: 비에고 | G2: 암베사 | H2: 제이스 | I2: 90 | J2: 405 | K2: 252 | L2: 62% | M2: =VLOOKUP(F2, roles!$A:$B,2,FALSE) -> 전사 | N2: 중립적 | P2: 행 레이블 | Q2: 공격적 | R2: 귀여운 | S2: 선정적 | T2: 성의없는 | U2: 암울한 | V2: 유머러스 | W2: 중립적 | X2: 캐릭터 | Y2: 프로팀 | Z2: (비어 있음) | AA2: 총합계
A3: 2 | B3: DK Sharvel | C3: #KR1 | D3: Challenger | E3: 2040 | F3: 바이 | G3: 키아나 | H3: 판테온 | I3: 965 | J3: 729 | K3: 584 | L3: 56% | M3: =VLOOKUP(F3, roles!$A:$B,2,FALSE) -> 전사 | N3: 프로팀 | P3: 마법사 | Q3: 0.03910918 | R3: 0.073329712 | S3: 0.0086909288 | T3: 0.059206953 | U3: 0.035850081 | V3: 0.13199348 | W3: 0.59804454 | X3: 0.034220532 | Y3: 0.01955459 | Z3: 0 | AA3: 1
A4: 3 | B4: T1 Guardian | C4: #KR3 | D4: Challenger | E4: 1967 | F4: 암베사 | G4: 크산테 | H4: 럼블 | I4: 496 | J4: 898 | K4: 763 | L4: 54% | M4: =VLOOKUP(F4, roles!$A:$B,2,FALSE) -> 전사 | N4: 프로팀 | P4: 서포터 | Q4: 0.054347826 | R4: 0.125 | S4: 0.0027173913 | T4: 0.035326087 | U4: 0.032608696 | V4: 0.13858696 | W4: 0.57336957 | X4: 0.032608696 | Y4: 0.0054347826 | Z4: 0 | AA4: 1
A5: 4 | B5: Phantasm | C5: #RANK1 | D5: Challenger | E5: 1950 | F5: 아크샨 | G5: 퀸 | H5: 흐웨이 | I5: 74 | J5: 304 | K5: 170 | L5: 64% | M5: =VLOOKUP(F5, roles!$A:$B,2,FALSE) -> 원거리 딜러 | N5: 중립적 | P5: 암살자 | Q5: 0.045634921 | R5: 0.069444444 | S5: 0.015873016 | T5: 0.05952381 | U5: 0.020833333 | V5: 0.12003968 | W5: 0.62797619 | X5: 0.032738095 | Y5: 0.0079365079 | Z5: 0 | AA5: 1
A6: 5 | B6: Effort | C6: #4444 | D6: Challenger | E6: 1936 | F6: 노틸러스 | G6: 브라움 | H6: 알리스타 | I6: 683 | J6: 412 | K6: 318 | L6: 56% | M6: =VLOOKUP(F6, roles!$A:$B,2,FALSE) -> 탱커 | N6: 중립적 | P6: 원거리 딜러 | Q6: 0.036031332 | R6: 0.072062663 | S6: 0.007310705 | T6: 0.05535248 | U6: 0.041253264 | V6: 0.11853786 | W6: 0.62245431 | X6: 0.02924282 | Y6: 0.017754569 | Z6: 0 | AA6: 1
A7: 6 | B7: LNG BuLLDoG | C7: #KR2 | D7: Challenger | E7: 1879 | F7: 아지르 | G7: 갈리오 | H7: 유나라 | I7: 765 | J7: 703 | K7: 559 | L7: 56% | M7: =VLOOKUP(F7, roles!$A:$B,2,FALSE) -> 마법사 | N7: 프로팀 | P7: 전사 | Q7: 0.03792715 | R7: 0.058956065 | S7: 0.010889974 | T7: 0.058205032 | U7: 0.039429215 | V7: 0.11866316 | W7: 0.62786331 | X7: 0.031918888 | Y7: 0.015771686 | Z7: 0.00037551633 | AA7: 1
A8: 7 | B8: 노익스강 | C8: #noex | D8: Challenger | E8: 1855 | F8: 자야 | G8: 이즈리얼 | H8: 시비르 | I8: 940 | J8: 679 | K8: 564 | L8: 55% | M8: =VLOOKUP(F8, roles!$A:$B,2,FALSE) -> 원거리 딜러 | N8: 중립적 | P8: 탱커 | Q8: 0.036211699 | R8: 0.075208914 | S8: 0.011142061 | T8: 0.058495822 | U8: 0.033426184 | V8: 0.11699164 | W8: 0.61652739 | X8: 0.038068709 | Y8: 0.013927577 | Z8: 0 | AA8: 1
A9: 8 | B9: DK Smash | C9: #KR7 | D9: Challenger | E9: 1837 | F9: 이즈리얼 | G9: 바루스 | H9: 카이사 | I9: 542 | J9: 449 | K9: 343 | L9: 57% | M9: =VLOOKUP(F9, roles!$A:$B,2,FALSE) -> 원거리 딜러 | N9: 프로팀 | P9: #N/A | Q9: 0.02 | R9: 0.14 | S9: 0 | T9: 0.12 | U9: 0.04 | V9: 0.16 | W9: 0.42 | X9: 0.1 | Y9: 0 | Z9: 0 | AA9: 1
A10: 9 | B10: 우 맨 | C10: #who | D10: Challenger | E10: 1794 | F10: 사일러스 | G10: 제이스 | H10: 아칼리 | I10: 493 | J10: 490 | K10: 382 | L10: 56% | M10: =VLOOKUP(F10, roles!$A:$B,2,FALSE) -> 마법사 | N10: 중립적 | P10: 총합계 | Q10: 0.039004707 | R10: 0.0710603 | S10: 0.0098632594 | T10: 0.057386236 | U10: 0.03597848 | V10: 0.12239408 | W10: 0.61578121 | X10: 0.033064335 | Y10: 0.015355302 | Z10: 0.00011208249 | AA10: 1
A11: 10 | B11: SeTab | C11: #123 | D11: Challenger | E11: 1779 | F11: 오로라 | G11: 라이즈 | H11: 오리아나 | I11: 698 | J11: 675 | K11: 577 | L11: 54% | M11: =VLOOKUP(F11, roles!$A:$B,2,FALSE) -> 마법사 | N11: 중립적
A12: 11 | B12: YdBB | C12: #0107 | D12: Challenger | E12: 1776 | F12: 뽀삐 | G12: 바드 | H12: 알리스타 | I12: 692 | J12: 540 | K12: 444 | L12: 55% | M12: =VLOOKUP(F12, roles!$A:$B,2,FALSE) -> 탱커 | N12: 중립적 | AB12: 1.79082
A13: 12 | B13: 젠레스존제로우 | C13: #KR1 | D13: Challenger | E13: 1734 | F13: 바루스 | G13: 이즈리얼 | H13: 유나라 | I13: 562 | J13: 942 | K13: 839 | L13: 53% | M13: =VLOOKUP(F13, roles!$A:$B,2,FALSE) -> 원거리 딜러 | N13: 중립적
A14: 13 | B14: daoxinwengu1 | C14: #KR1 | D14: Challenger | E14: 1725 | F14: 진 | G14: 이즈리얼 | H14: 카이사 | I14: 496 | J14: 746 | K14: 619 | L14: 55% | M14: =VLOOKUP(F14, roles!$A:$B,2,FALSE) -> 원거리 딜러 | N14: 중립적
A15: 14 | B15: Vincenzo | C15: #kr40 | D15: Challenger | E15: 1720 | F15: 리 신 | G15: 판테온 | H15: 신 짜오 | I15: 723 | J15: 676 | K15: 581 | L15: 54% | M15: =VLOOKUP(F15, roles!$A:$B,2,FALSE) -> 전사 | N15: 중립적 | P15: 행 레이블 | Q15: 공격적 | R15: 귀여운 | S15: 선정적 | T15: 성의없는 | U15: 암울한 | V15: 유머러스 | W15: 중립적 | X15: 캐릭터 | Y15: 프로팀 | Z15: (비어 있음) | AA15: 총합계 | AB15: 공격적 | AC15: 귀여운 | AD15: 선정적 | AE15: 성의없는 | AF15: 암울한 | AG15: 유머러스 | AH15: 중립적 | AI15: 캐릭터 | AJ15: 프로팀 | AK15: 총합
A16: 15 | B16: DNF Berserker | C16: #6666 | D16: Challenger | E16: 1709 | F16: 이즈리얼 | G16: 유나라 | H16: 코르키 | I16: 592 | J16: 608 | K16: 508 | L16: 54% | M16: =VLOOKUP(F16, roles!$A:$B,2,FALSE) -> 원거리 딜러 | N16: 중립적 | P16: 마법사 | Q16: 72 | R16: 135 | S16: 16 | T16: 109 | U16: 66 | V16: 243 | W16: 1101 | X16: 63 | Y16: 36 | AA16: 1841 | AB16: =Q16/$AA16 -> 0.03910918 | AC16: =R16/$AA16 -> 0.073329712 | AD16: =S16/$AA16 -> 0.0086909288 | AE16: =T16/$AA16 -> 0.059206953 | AF16: =U16/$AA16 -> 0.035850081 | AG16: =V16/$AA16 -> 0.13199348 | AH16: =W16/$AA16 -> 0.59804454 | AI16: =X16/$AA16 -> 0.034220532 | AJ16: =Y16/$AA16 -> 0.01955459 | AK16: =SUM(AB16:AJ16) -> 1
A17: 16 | B17: DK ShowMaker | C17: #KR1 | D17: Challenger | E17: 1701 | F17: 르블랑 | G17: 탈리야 | H17: 사일러스 | I17: 604 | J17: 491 | K17: 375 | L17: 57% | M17: =VLOOKUP(F17, roles!$A:$B,2,FALSE) -> 암살자 | N17: 프로팀 | P17: 서포터 | Q17: 20 | R17: 46 | S17: 1 | T17: 13 | U17: 12 | V17: 51 | W17: 211 | X17: 12 | Y17: 2 | AA17: 368 | AB17: =Q17/$AA17 -> 0.054347826 | AC17: =R17/$AA17 -> 0.125 | AD17: =S17/$AA17 -> 0.0027173913 | AE17: =T17/$AA17 -> 0.035326087 | AF17: =U17/$AA17 -> 0.032608696 | AG17: =V17/$AA17 -> 0.13858696 | AH17: =W17/$AA17 -> 0.57336957 | AI17: =X17/$AA17 -> 0.032608696 | AJ17: =Y17/$AA17 -> 0.0054347826 | AK17: =SUM(AB17:AJ17) -> 1
A18: 17 | B18: T1 구름 | C18: #2007 | D18: Challenger | E18: 1696 | F18: 알리스타 | G18: 뽀삐 | H18: 라칸 | I18: 601 | J18: 691 | K18: 585 | L18: 54% | M18: =VLOOKUP(F18, roles!$A:$B,2,FALSE) -> 탱커 | N18: 프로팀 | P18: 암살자 | Q18: 46 | R18: 70 | S18: 16 | T18: 60 | U18: 21 | V18: 121 | W18: 633 | X18: 33 | Y18: 8 | AA18: 1008 | AB18: =Q18/$AA18 -> 0.045634921 | AC18: =R18/$AA18 -> 0.069444444 | AD18: =S18/$AA18 -> 0.015873016 | AE18: =T18/$AA18 -> 0.05952381 | AF18: =U18/$AA18 -> 0.020833333 | AG18: =V18/$AA18 -> 0.12003968 | AH18: =W18/$AA18 -> 0.62797619 | AI18: =X18/$AA18 -> 0.032738095 | AJ18: =Y18/$AA18 -> 0.0079365079 | AK18: =SUM(AB18:AJ18) -> 1
A19: 18 | B19: Aileri | C19: #KR1 | D19: Challenger | E19: 1677 | F19: 이렐리아 | G19: 아칼리 | H19: 라칸 | I19: 401 | J19: 314 | K19: 230 | L19: 58% | M19: =VLOOKUP(F19, roles!$A:$B,2,FALSE) -> 전사 | N19: 중립적 | P19: 원거리 딜러 | Q19: 69 | R19: 138 | S19: 14 | T19: 106 | U19: 79 | V19: 227 | W19: 1192 | X19: 56 | Y19: 34 | AA19: 1915 | AB19: =Q19/$AA19 -> 0.036031332 | AC19: =R19/$AA19 -> 0.072062663 | AD19: =S19/$AA19 -> 0.007310705 | AE19: =T19/$AA19 -> 0.05535248 | AF19: =U19/$AA19 -> 0.041253264 | AG19: =V19/$AA19 -> 0.11853786 | AH19: =W19/$AA19 -> 0.62245431 | AI19: =X19/$AA19 -> 0.02924282 | AJ19: =Y19/$AA19 -> 0.017754569 | AK19: =SUM(AB19:AJ19) -> 1
A20: 19 | B20: 베베핑크 | C20: #KR1 | D20: Challenger | E20: 1672 | F20: 제이스 | G20: 신드라 | H20: 요네 | I20: 114 | J20: 387 | K20: 273 | L20: 59% | M20: =VLOOKUP(F20, roles!$A:$B,2,FALSE) -> 전사 | N20: 중립적 | P20: 전사 | Q20: 101 | R20: 157 | S20: 29 | T20: 155 | U20: 105 | V20: 316 | W20: 1672 | X20: 85 | Y20: 42 | Z20: 1 | AA20: 2663 | AB20: =Q20/$AA20 -> 0.03792715 | AC20: =R20/$AA20 -> 0.058956065 | AD20: =S20/$AA20 -> 0.010889974 | AE20: =T20/$AA20 -> 0.058205032 | AF20: =U20/$AA20 -> 0.039429215 | AG20: =V20/$AA20 -> 0.11866316 | AH20: =W20/$AA20 -> 0.62786331 | AI20: =X20/$AA20 -> 0.031918888 | AJ20: =Y20/$AA20 -> 0.015771686 | AK20: =SUM(AB20:AJ20) -> 0.99962448
A21: 20 | B21: DK Lucid | C21: #KR1 | D21: Challenger | E21: 1668 | F21: 카이사 | G21: 리 신 | H21: 루시안 | I21: 738 | J21: 581 | K21: 490 | L21: 54% | M21: =VLOOKUP(F21, roles!$A:$B,2,FALSE) -> 원거리 딜러 | N21: 프로팀 | P21: 탱커 | Q21: 39 | R21: 81 | S21: 12 | T21: 63 | U21: 36 | V21: 126 | W21: 664 | X21: 41 | Y21: 15 | AA21: 1077 | AB21: =Q21/$AA21 -> 0.036211699 | AC21: =R21/$AA21 -> 0.075208914 | AD21: =S21/$AA21 -> 0.011142061 | AE21: =T21/$AA21 -> 0.058495822 | AF21: =U21/$AA21 -> 0.033426184 | AG21: =V21/$AA21 -> 0.11699164 | AH21: =W21/$AA21 -> 0.61652739 | AI21: =X21/$AA21 -> 0.038068709 | AJ21: =Y21/$AA21 -> 0.013927577 | AK21: =SUM(AB21:AJ21) -> 1
A22: 21 | B22: 타상연화 | C22: #123 | D22: Challenger | E22: 1666 | F22: 탈리야 | G22: 오리아나 | H22: 아지르 | I22: 1224 | J22: 1162 | K22: 1055 | L22: 52% | M22: =VLOOKUP(F22, roles!$A:$B,2,FALSE) -> 마법사 | N22: 중립적 | P22: #N/A | Q22: 1 | R22: 7 | T22: 6 | U22: 2 | V22: 8 | W22: 21 | X22: 5 | AA22: 50
A23: 22 | B23: Katie sky | C23: #KR2 | D23: Challenger | E23: 1651 | F23: 미스 포츈 | G23: 루시안 | H23: 카이사 | I23: 689 | J23: 1075 | K23: 993 | L23: 52% | M23: =VLOOKUP(F23, roles!$A:$B,2,FALSE) -> 원거리 딜러 | N23: 중립적 | P23: 총합계 | Q23: 348 | R23: 634 | S23: 88 | T23: 512 | U23: 321 | V23: 1092 | W23: 5494 | X23: 295 | Y23: 137 | Z23: 1 | AA23: 8922
A24: 23 | B24: Sylvie | C24: #77777 | D24: Challenger | E24: 1624 | F24: 리 신 | G24: 제드 | H24: 신 짜오 | I24: 816 | J24: 751 | K24: 684 | L24: 52% | M24: =VLOOKUP(F24, roles!$A:$B,2,FALSE) -> 전사 | N24: 중립적 | P24: 마법사 | Q24: =Q16/Q$23 -> 0.20689655 | R24: =R16/R$23 -> 0.21293375 | S24: =S16/S$23 -> 0.18181818 | T24: =T16/T$23 -> 0.21289062 | U24: =U16/U$23 -> 0.20560748 | V24: =V16/V$23 -> 0.22252747 | W24: =W16/W$23 -> 0.20040044 | X24: =X16/X$23 -> 0.21355932 | Y24: =Y16/Y$23 -> 0.26277372
A25: 24 | B25: 기리보이혁갓 | C25: #아입니두 | D25: Challenger | E25: 1623 | F25: 잭스 | G25: 피오라 | H25: 이렐리아 | I25: 444 | J25: 781 | K25: 693 | L25: 53% | M25: =VLOOKUP(F25, roles!$A:$B,2,FALSE) -> 전사 | N25: 유머러스 | P25: 서포터 | Q25: =Q17/Q$23 -> 0.057471264 | R25: =R17/R$23 -> 0.072555205 | S25: =S17/S$23 -> 0.011363636 | T25: =T17/T$23 -> 0.025390625 | U25: =U17/U$23 -> 0.037383178 | V25: =V17/V$23 -> 0.046703297 | W25: =W17/W$23 -> 0.038405533 | X25: =X17/X$23 -> 0.040677966 | Y25: =Y17/Y$23 -> 0.01459854
A26: 25 | B26: 따봉 람머스 | C26: #KR1 | D26: Challenger | E26: 1614 | F26: 암베사 | G26: 그웬 | H26: 제이스 | I26: 879 | J26: 791 | K26: 693 | L26: 53% | M26: =VLOOKUP(F26, roles!$A:$B,2,FALSE) -> 전사 | N26: 중립적 | P26: 암살자 | Q26: =Q18/Q$23 -> 0.13218391 | R26: =R18/R$23 -> 0.11041009 | S26: =S18/S$23 -> 0.18181818 | T26: =T18/T$23 -> 0.1171875 | U26: =U18/U$23 -> 0.065420561 | V26: =V18/V$23 -> 0.11080586 | W26: =W18/W$23 -> 0.1152166 | X26: =X18/X$23 -> 0.11186441 | Y26: =Y18/Y$23 -> 0.058394161
A27: 26 | B27: DNF Quantum | C27: #KR 1 | D27: Challenger | E27: 1611 | F27: 노틸러스 | G27: 알리스타 | H27: 렐 | I27: 708 | J27: 919 | K27: 825 | L27: 53% | M27: =VLOOKUP(F27, roles!$A:$B,2,FALSE) -> 탱커 | N27: 중립적 | P27: 원거리 딜러 | Q27: =Q19/Q$23 -> 0.19827586 | R27: =R19/R$23 -> 0.21766562 | S27: =S19/S$23 -> 0.15909091 | T27: =T19/T$23 -> 0.20703125 | U27: =U19/U$23 -> 0.24610592 | V27: =V19/V$23 -> 0.20787546 | W27: =W19/W$23 -> 0.21696396 | X27: =X19/X$23 -> 0.18983051 | Y27: =Y19/Y$23 -> 0.24817518
A28: 27 | B28: DRX Willer | C28: #DRX | D28: Challenger | E28: 1602 | F28: 리 신 | G28: 판테온 | H28: 제이스 | I28: 341 | J28: 352 | K28: 261 | L28: 57% | M28: =VLOOKUP(F28, roles!$A:$B,2,FALSE) -> 전사 | N28: 프로팀 | P28: 전사 | Q28: =Q20/Q$23 -> 0.29022989 | R28: =R20/R$23 -> 0.24763407 | S28: =S20/S$23 -> 0.32954545 | T28: =T20/T$23 -> 0.30273438 | U28: =U20/U$23 -> 0.3271028 | V28: =V20/V$23 -> 0.28937729 | W28: =W20/W$23 -> 0.304332 | X28: =X20/X$23 -> 0.28813559 | Y28: =Y20/Y$23 -> 0.30656934
A29: 28 | B29: Frog | C29: #DRX | D29: Challenger | E29: 1599 | F29: 제이스 | G29: 암베사 | H29: 럼블 | I29: 475 | J29: 433 | K29: 351 | L29: 55% | M29: =VLOOKUP(F29, roles!$A:$B,2,FALSE) -> 전사 | N29: 중립적 | P29: 탱커 | Q29: =Q21/Q$23 -> 0.11206897 | R29: =R21/R$23 -> 0.12776025 | S29: =S21/S$23 -> 0.13636364 | T29: =T21/T$23 -> 0.12304688 | U29: =U21/U$23 -> 0.11214953 | V29: =V21/V$23 -> 0.11538462 | W29: =W21/W$23 -> 0.12085912 | X29: =X21/X$23 -> 0.13898305 | Y29: =Y21/Y$23 -> 0.10948905
A30: 29 | B30: FURIA Ayu | C30: #1103 | D30: Challenger | E30: 1595 | F30: 카이사 | G30: 니달리 | H30: 이즈리얼 | I30: 68 | J30: 272 | K30: 172 | L30: 61% | M30: =VLOOKUP(F30, roles!$A:$B,2,FALSE) -> 원거리 딜러 | N30: 중립적 | Q30: =SUM(Q24:Q29) -> 0.99712644 | R30: =SUM(R24:R29) -> 0.98895899 | S30: =SUM(S24:S29) -> 1 | T30: =SUM(T24:T29) -> 0.98828125 | U30: =SUM(U24:U29) -> 0.99376947 | V30: =SUM(V24:V29) -> 0.99267399 | W30: =SUM(W24:W29) -> 0.99617765 | X30: =SUM(X24:X29) -> 0.98305085 | Y30: =SUM(Y24:Y29) -> 1
A31: 30 | B31: 애딘데용 | C31: #느에엥 | D31: Challenger | E31: 1594 | F31: 신지드 | G31: 사이온 | H31: 암베사 | I31: 911 | J31: 928 | K31: 853 | L31: 52% | M31: =VLOOKUP(F31, roles!$A:$B,2,FALSE) -> 탱커 | N31: 중립적
A32: 31 | B32: 어쩌라고맞짱뜰까 | C32: #HOYA | D32: Challenger | E32: 1586 | F32: 제이스 | G32: 암베사 | H32: 럼블 | I32: 695 | J32: 587 | K32: 504 | L32: 54% | M32: =VLOOKUP(F32, roles!$A:$B,2,FALSE) -> 전사 | N32: 중립적
A33: 32 | B33: Shylie | C33: #KR1 | D33: Challenger | E33: 1585 | F33: 바이 | G33: 비에고 | H33: 리 신 | I33: 516 | J33: 579 | K33: 484 | L33: 54% | M33: =VLOOKUP(F33, roles!$A:$B,2,FALSE) -> 전사 | N33: 중립적
A34: 33 | B34: L0KEY | C34: #loki | D34: Challenger | E34: 1580 | F34: 아지르 | G34: 오리아나 | H34: 요네 | I34: 1035 | J34: 292 | K34: 206 | L34: 59% | M34: =VLOOKUP(F34, roles!$A:$B,2,FALSE) -> 마법사 | N34: 중립적
A35: 34 | B35: 자신감을잃지말자 | C35: #KR1 | D35: Challenger | E35: 1577 | F35: 암베사 | G35: 제이스 | H35: 크산테 | I35: 615 | J35: 714 | K35: 644 | L35: 53% | M35: =VLOOKUP(F35, roles!$A:$B,2,FALSE) -> 전사 | N35: 중립적
A36: 35 | B36: Aimyon | C36: #0409 | D36: Challenger | E36: 1569 | F36: 오리아나 | G36: 빅토르 | H36: 요네 | I36: 917 | J36: 599 | K36: 535 | L36: 53% | M36: =VLOOKUP(F36, roles!$A:$B,2,FALSE) -> 마법사 | N36: 중립적
A37: 36 | B37: DK Career | C37: #KR7 | D37: Challenger | E37: 1567 | F37: 뽀삐 | G37: 파이크 | H37: 바드 | I37: 391 | J37: 810 | K37: 717 | L37: 53% | M37: =VLOOKUP(F37, roles!$A:$B,2,FALSE) -> 탱커 | N37: 프로팀
A38: 37 | B38: TheHank | C38: #Xhh | D38: Challenger | E38: 1548 | F38: 렐 | G38: 노틸러스 | H38: 뽀삐 | I38: 123 | J38: 404 | K38: 314 | L38: 56% | M38: =VLOOKUP(F38, roles!$A:$B,2,FALSE) -> 탱커 | N38: 중립적
A39: 38 | B39: 라쿤99 | C39: #KR1 | D39: Challenger | E39: 1546 | F39: 자이라 | G39: 직스 | H39: 킨드레드 | I39: 742 | J39: 579 | K39: 506 | L39: 53% | M39: =VLOOKUP(F39, roles!$A:$B,2,FALSE) -> 마법사 | N39: 중립적
A40: 39 | B40: NASA | C40: #쟁 구 | D40: Challenger | E40: 1541 | F40: 트리스타나 | G40: 미스 포츈 | H40: 코르키 | I40: 166 | J40: 307 | K40: 234 | L40: 57% | M40: =VLOOKUP(F40, roles!$A:$B,2,FALSE) -> 원거리 딜러 | N40: 중립적
...

Sheet roles
A1: 챔피언 이름 | B1: 역할군 (Primary Role)
A2: 가렌 | B2: 전사
A3: 갈리오 | B3: 탱커
A4: 갱플랭크 | B4: 전사
A5: 그라가스 | B5: 탱커
A6: 그레이브즈 | B6: 전사
A7: 그웬 | B7: 전사
A8: 나르 | B8: 전사
A9: 나미 | B9: 서포터
A10: 나서스 | B10: 전사
A11: 나피리 | B11: 암살자
A12: 노틸러스 | B12: 탱커
... A176: 벡스 | B176: 마법사

Sheet Sheet2
B2: 행 레이블 | C2: 공격적 | D2: 귀여운 | E2: 선정적 | F2: 성의없는 | G2: 암울한 | H2: 유머러스 | I2: 중립적 | J2: 캐릭터 | K2: 프로팀 | L2: (비어 있음) | M2: 총합계
B3: 마법사 | C3: 0.03910918 | D3: 0.073329712 | E3: 0.0086909288 | F3: 0.059206953 | G3: 0.035850081 | H3: 0.13199348 | I3: 0.59804454 | J3: 0.034220532 | K3: 0.01955459 | L3: 0 | M3: 1 | O3: 0.059206953
B4: 서포터 | C4: 0.054347826 | D4: 0.125 | E4: 0.0027173913 | F4: 0.035326087 | G4: 0.032608696 | H4: 0.13858696 | I4: 0.57336957 | J4: 0.032608696 | K4: 0.0054347826 | L4: 0 | M4: 1 | P4: 0.035326087
B5: 암살자 | C5: 0.045634921 | D5: 0.069444444 | E5: 0.015873016 | F5: 0.05952381 | G5: 0.020833333 | H5: 0.12003968 | I5: 0.62797619 | J5: 0.032738095 | K5: 0.0079365079 | L5: 0 | M5: 1 | O5: 0.05952381
B6: 원거리 딜러 | C6: 0.036031332 | D6: 0.072062663 | E6: 0.007310705 | F6: 0.05535248 | G6: 0.041253264 | H6: 0.11853786 | I6: 0.62245431 | J6: 0.02924282 | K6: 0.017754569 | L6: 0 | M6: 1 | O6: 0.05535248
B7: 전사 | C7: 0.03792715 | D7: 0.058956065 | E7: 0.010889974 | F7: 0.058205032 | G7: 0.039429215 | H7: 0.11866316 | I7: 0.62786331 | J7: 0.031918888 | K7: 0.015771686 | L7: 0.00037551633 | M7: 1 | O7: 0.058205032
B8: 탱커 | C8: 0.036211699 | D8: 0.075208914 | E8: 0.011142061 | F8: 0.058495822 | G8: 0.033426184 | H8: 0.11699164 | I8: 0.61652739 | J8: 0.038068709 | K8: 0.013927577 | L8: 0 | M8: 1 | O8: 0.058495822
B9: #N/A | C9: 0.02 | D9: 0.14 | E9: 0 | F9: 0.12 | G9: 0.04 | H9: 0.16 | I9: 0.42 | J9: 0.1 | K9: 0 | L9: 0 | M9: 1
B10: 총합계 | C10: 0.039004707 | D10: 0.0710603 | E10: 0.0098632594 | F10: 0.057386236 | G10: 0.03597848 | H10: 0.12239408 | I10: 0.61578121 | J10: 0.033064335 | K10: 0.015355302 | L10: 0.00011208249 | M10: 1 | O10: =AVERAGE(O3:O8) -> 0.058156819 | P10: =O10/P4 -> 1.6462853
